[2025-10-17T14:11:01.598+0000] {local_task_job_runner.py:123} INFO - ::group::Pre task execution logs
[2025-10-17T14:11:01.644+0000] {taskinstance.py:2614} INFO - Dependencies all met for dep_context=non-requeueable deps ti=<TaskInstance: etl_datalake_hive_iceberg.load_bronze manual__2025-10-17T14:11:00.565550+00:00 [queued]>
[2025-10-17T14:11:01.660+0000] {taskinstance.py:2614} INFO - Dependencies all met for dep_context=requeueable deps ti=<TaskInstance: etl_datalake_hive_iceberg.load_bronze manual__2025-10-17T14:11:00.565550+00:00 [queued]>
[2025-10-17T14:11:01.661+0000] {taskinstance.py:2867} INFO - Starting attempt 1 of 2
[2025-10-17T14:11:01.682+0000] {taskinstance.py:2890} INFO - Executing <Task(BashOperator): load_bronze> on 2025-10-17 14:11:00.565550+00:00
[2025-10-17T14:11:01.689+0000] {standard_task_runner.py:72} INFO - Started process 74 to run task
[2025-10-17T14:11:01.698+0000] {standard_task_runner.py:104} INFO - Running: ['***', 'tasks', 'run', 'etl_datalake_hive_iceberg', 'load_bronze', 'manual__2025-10-17T14:11:00.565550+00:00', '--job-id', '29', '--raw', '--subdir', 'DAGS_FOLDER/etl_datalake_dag.py', '--cfg-path', '/tmp/tmpsr0sira5']
[2025-10-17T14:11:01.700+0000] {standard_task_runner.py:105} INFO - Job 29: Subtask load_bronze
[2025-10-17T14:11:01.755+0000] {warnings.py:109} WARNING - /home/***/.local/lib/python3.8/site-packages/***/settings.py:209: DeprecationWarning: The sql_alchemy_conn option in [core] has been moved to the sql_alchemy_conn option in [database] - the old setting has been used, but please update your config.
  SQL_ALCHEMY_CONN = conf.get("database", "SQL_ALCHEMY_CONN")

[2025-10-17T14:11:01.862+0000] {task_command.py:467} INFO - Running <TaskInstance: etl_datalake_hive_iceberg.load_bronze manual__2025-10-17T14:11:00.565550+00:00 [running]> on host 1432f256adfc
[2025-10-17T14:11:02.000+0000] {taskinstance.py:3134} INFO - Exporting env vars: AIRFLOW_CTX_DAG_EMAIL='alert@datateam.local' AIRFLOW_CTX_DAG_OWNER='***' AIRFLOW_CTX_DAG_ID='etl_datalake_hive_iceberg' AIRFLOW_CTX_TASK_ID='load_bronze' AIRFLOW_CTX_EXECUTION_DATE='2025-10-17T14:11:00.565550+00:00' AIRFLOW_CTX_TRY_NUMBER='1' AIRFLOW_CTX_DAG_RUN_ID='manual__2025-10-17T14:11:00.565550+00:00'
[2025-10-17T14:11:02.002+0000] {taskinstance.py:732} INFO - ::endgroup::
[2025-10-17T14:11:02.030+0000] {subprocess.py:78} INFO - Tmp dir root location: /tmp
[2025-10-17T14:11:02.033+0000] {subprocess.py:88} INFO - Running command: ['/bin/bash', '-c', '\n        docker exec spark-submit /opt/spark/bin/spark-submit         --master spark://spark-master:7077         --deploy-mode client         /opt/***/scripts/Load_Bronze.py\n        ']
[2025-10-17T14:11:02.052+0000] {subprocess.py:99} INFO - Output:
[2025-10-17T14:11:04.267+0000] {subprocess.py:106} INFO - python3: can't open file '/opt/***/scripts/Load_Bronze.py': [Errno 2] No such file or directory
[2025-10-17T14:11:04.284+0000] {subprocess.py:106} INFO - 25/10/17 14:11:04 INFO ShutdownHookManager: Shutdown hook called
[2025-10-17T14:11:04.288+0000] {subprocess.py:106} INFO - 25/10/17 14:11:04 INFO ShutdownHookManager: Deleting directory /tmp/spark-9c9b3db8-972d-4929-bf7a-126eb39afffd
[2025-10-17T14:11:04.314+0000] {subprocess.py:110} INFO - Command exited with return code 2
[2025-10-17T14:11:04.338+0000] {taskinstance.py:3313} ERROR - Task failed with exception
Traceback (most recent call last):
  File "/home/airflow/.local/lib/python3.8/site-packages/airflow/models/taskinstance.py", line 768, in _execute_task
    result = _execute_callable(context=context, **execute_callable_kwargs)
  File "/home/airflow/.local/lib/python3.8/site-packages/airflow/models/taskinstance.py", line 734, in _execute_callable
    return ExecutionCallableRunner(
  File "/home/airflow/.local/lib/python3.8/site-packages/airflow/utils/operator_helpers.py", line 252, in run
    return self.func(*args, **kwargs)
  File "/home/airflow/.local/lib/python3.8/site-packages/airflow/models/baseoperator.py", line 424, in wrapper
    return func(self, *args, **kwargs)
  File "/home/airflow/.local/lib/python3.8/site-packages/airflow/operators/bash.py", line 276, in execute
    raise AirflowException(
airflow.exceptions.AirflowException: Bash command failed. The command returned a non-zero exit code 2.
[2025-10-17T14:11:04.368+0000] {taskinstance.py:1226} INFO - Marking task as UP_FOR_RETRY. dag_id=etl_datalake_hive_iceberg, task_id=load_bronze, run_id=manual__2025-10-17T14:11:00.565550+00:00, execution_date=20251017T141100, start_date=20251017T141101, end_date=20251017T141104
[2025-10-17T14:11:04.469+0000] {taskinstance.py:341} INFO - ::group::Post task execution logs
[2025-10-17T14:11:04.470+0000] {standard_task_runner.py:124} ERROR - Failed to execute job 29 for task load_bronze (Bash command failed. The command returned a non-zero exit code 2.; 74)
Traceback (most recent call last):
  File "/home/airflow/.local/lib/python3.8/site-packages/airflow/task/task_runner/standard_task_runner.py", line 117, in _start_by_fork
    ret = args.func(args, dag=self.dag)
  File "/home/airflow/.local/lib/python3.8/site-packages/airflow/cli/cli_config.py", line 49, in command
    return func(*args, **kwargs)
  File "/home/airflow/.local/lib/python3.8/site-packages/airflow/utils/cli.py", line 116, in wrapper
    return f(*args, **kwargs)
  File "/home/airflow/.local/lib/python3.8/site-packages/airflow/cli/commands/task_command.py", line 483, in task_run
    task_return_code = _run_task_by_selected_method(args, _dag, ti)
  File "/home/airflow/.local/lib/python3.8/site-packages/airflow/cli/commands/task_command.py", line 256, in _run_task_by_selected_method
    return _run_raw_task(args, ti)
  File "/home/airflow/.local/lib/python3.8/site-packages/airflow/cli/commands/task_command.py", line 341, in _run_raw_task
    return ti._run_raw_task(
  File "/home/airflow/.local/lib/python3.8/site-packages/airflow/utils/session.py", line 97, in wrapper
    return func(*args, session=session, **kwargs)
  File "/home/airflow/.local/lib/python3.8/site-packages/airflow/models/taskinstance.py", line 3006, in _run_raw_task
    return _run_raw_task(
  File "/home/airflow/.local/lib/python3.8/site-packages/airflow/models/taskinstance.py", line 274, in _run_raw_task
    TaskInstance._execute_task_with_callbacks(
  File "/home/airflow/.local/lib/python3.8/site-packages/airflow/models/taskinstance.py", line 3161, in _execute_task_with_callbacks
    result = self._execute_task(context, task_orig)
  File "/home/airflow/.local/lib/python3.8/site-packages/airflow/models/taskinstance.py", line 3185, in _execute_task
    return _execute_task(self, context, task_orig)
  File "/home/airflow/.local/lib/python3.8/site-packages/airflow/models/taskinstance.py", line 768, in _execute_task
    result = _execute_callable(context=context, **execute_callable_kwargs)
  File "/home/airflow/.local/lib/python3.8/site-packages/airflow/models/taskinstance.py", line 734, in _execute_callable
    return ExecutionCallableRunner(
  File "/home/airflow/.local/lib/python3.8/site-packages/airflow/utils/operator_helpers.py", line 252, in run
    return self.func(*args, **kwargs)
  File "/home/airflow/.local/lib/python3.8/site-packages/airflow/models/baseoperator.py", line 424, in wrapper
    return func(self, *args, **kwargs)
  File "/home/airflow/.local/lib/python3.8/site-packages/airflow/operators/bash.py", line 276, in execute
    raise AirflowException(
airflow.exceptions.AirflowException: Bash command failed. The command returned a non-zero exit code 2.
[2025-10-17T14:11:04.521+0000] {local_task_job_runner.py:266} INFO - Task exited with return code 1
[2025-10-17T14:11:04.574+0000] {taskinstance.py:3901} INFO - 0 downstream tasks scheduled from follow-on schedule check
[2025-10-17T14:11:04.577+0000] {local_task_job_runner.py:245} INFO - ::endgroup::
