[2025-10-17T14:10:47.644+0000] {local_task_job_runner.py:123} INFO - ::group::Pre task execution logs
[2025-10-17T14:10:47.676+0000] {taskinstance.py:2614} INFO - Dependencies all met for dep_context=non-requeueable deps ti=<TaskInstance: etl_datalake_hive_iceberg.load_bronze manual__2025-10-17T14:00:44.222739+00:00 [queued]>
[2025-10-17T14:10:47.687+0000] {taskinstance.py:2614} INFO - Dependencies all met for dep_context=requeueable deps ti=<TaskInstance: etl_datalake_hive_iceberg.load_bronze manual__2025-10-17T14:00:44.222739+00:00 [queued]>
[2025-10-17T14:10:47.687+0000] {taskinstance.py:2867} INFO - Starting attempt 2 of 2
[2025-10-17T14:10:47.699+0000] {taskinstance.py:2890} INFO - Executing <Task(BashOperator): load_bronze> on 2025-10-17 14:00:44.222739+00:00
[2025-10-17T14:10:47.703+0000] {standard_task_runner.py:72} INFO - Started process 59 to run task
[2025-10-17T14:10:47.707+0000] {standard_task_runner.py:104} INFO - Running: ['***', 'tasks', 'run', 'etl_datalake_hive_iceberg', 'load_bronze', 'manual__2025-10-17T14:00:44.222739+00:00', '--job-id', '28', '--raw', '--subdir', 'DAGS_FOLDER/etl_datalake_dag.py', '--cfg-path', '/tmp/tmpit8xhsjq']
[2025-10-17T14:10:47.709+0000] {standard_task_runner.py:105} INFO - Job 28: Subtask load_bronze
[2025-10-17T14:10:47.733+0000] {warnings.py:109} WARNING - /home/***/.local/lib/python3.8/site-packages/***/settings.py:209: DeprecationWarning: The sql_alchemy_conn option in [core] has been moved to the sql_alchemy_conn option in [database] - the old setting has been used, but please update your config.
  SQL_ALCHEMY_CONN = conf.get("database", "SQL_ALCHEMY_CONN")

[2025-10-17T14:10:47.806+0000] {task_command.py:467} INFO - Running <TaskInstance: etl_datalake_hive_iceberg.load_bronze manual__2025-10-17T14:00:44.222739+00:00 [running]> on host 1432f256adfc
[2025-10-17T14:10:47.912+0000] {taskinstance.py:3134} INFO - Exporting env vars: AIRFLOW_CTX_DAG_EMAIL='alert@datateam.local' AIRFLOW_CTX_DAG_OWNER='***' AIRFLOW_CTX_DAG_ID='etl_datalake_hive_iceberg' AIRFLOW_CTX_TASK_ID='load_bronze' AIRFLOW_CTX_EXECUTION_DATE='2025-10-17T14:00:44.222739+00:00' AIRFLOW_CTX_TRY_NUMBER='2' AIRFLOW_CTX_DAG_RUN_ID='manual__2025-10-17T14:00:44.222739+00:00'
[2025-10-17T14:10:47.913+0000] {taskinstance.py:732} INFO - ::endgroup::
[2025-10-17T14:10:47.930+0000] {subprocess.py:78} INFO - Tmp dir root location: /tmp
[2025-10-17T14:10:47.931+0000] {subprocess.py:88} INFO - Running command: ['/bin/bash', '-c', '\n        docker exec spark-submit /opt/spark/bin/spark-submit         --master spark://spark-master:7077         --deploy-mode client         /opt/***/scripts/Load_Bronze.py\n        ']
[2025-10-17T14:10:47.941+0000] {subprocess.py:99} INFO - Output:
[2025-10-17T14:10:51.869+0000] {subprocess.py:106} INFO - python3: can't open file '/opt/***/scripts/Load_Bronze.py': [Errno 2] No such file or directory
[2025-10-17T14:10:51.907+0000] {subprocess.py:106} INFO - 25/10/17 14:10:51 INFO ShutdownHookManager: Shutdown hook called
[2025-10-17T14:10:51.912+0000] {subprocess.py:106} INFO - 25/10/17 14:10:51 INFO ShutdownHookManager: Deleting directory /tmp/spark-a6a59cc3-d835-400e-b930-2d945932252f
[2025-10-17T14:10:51.990+0000] {subprocess.py:110} INFO - Command exited with return code 2
[2025-10-17T14:10:52.036+0000] {taskinstance.py:3313} ERROR - Task failed with exception
Traceback (most recent call last):
  File "/home/airflow/.local/lib/python3.8/site-packages/airflow/models/taskinstance.py", line 768, in _execute_task
    result = _execute_callable(context=context, **execute_callable_kwargs)
  File "/home/airflow/.local/lib/python3.8/site-packages/airflow/models/taskinstance.py", line 734, in _execute_callable
    return ExecutionCallableRunner(
  File "/home/airflow/.local/lib/python3.8/site-packages/airflow/utils/operator_helpers.py", line 252, in run
    return self.func(*args, **kwargs)
  File "/home/airflow/.local/lib/python3.8/site-packages/airflow/models/baseoperator.py", line 424, in wrapper
    return func(self, *args, **kwargs)
  File "/home/airflow/.local/lib/python3.8/site-packages/airflow/operators/bash.py", line 276, in execute
    raise AirflowException(
airflow.exceptions.AirflowException: Bash command failed. The command returned a non-zero exit code 2.
[2025-10-17T14:10:52.046+0000] {taskinstance.py:1226} INFO - Marking task as FAILED. dag_id=etl_datalake_hive_iceberg, task_id=load_bronze, run_id=manual__2025-10-17T14:00:44.222739+00:00, execution_date=20251017T140044, start_date=20251017T141047, end_date=20251017T141052
[2025-10-17T14:10:52.111+0000] {warnings.py:109} WARNING - /home/***/.local/lib/python3.8/site-packages/***/utils/email.py:155: RemovedInAirflow3Warning: Fetching SMTP credentials from configuration variables will be deprecated in a future release. Please set credentials using a connection instead.
  send_mime_email(e_from=mail_from, e_to=recipients, mime_msg=msg, conn_id=conn_id, dryrun=dryrun)

[2025-10-17T14:10:52.112+0000] {configuration.py:1074} WARNING - section/key [smtp/smtp_user] not found in config
[2025-10-17T14:10:52.113+0000] {email.py:272} INFO - Email alerting: attempt 1
[2025-10-17T14:10:52.170+0000] {configuration.py:1074} WARNING - section/key [smtp/smtp_user] not found in config
[2025-10-17T14:10:52.171+0000] {email.py:272} INFO - Email alerting: attempt 1
[2025-10-17T14:10:52.175+0000] {taskinstance.py:1235} ERROR - Failed to send email to: ['alert@datateam.local']
Traceback (most recent call last):
  File "/home/airflow/.local/lib/python3.8/site-packages/airflow/models/taskinstance.py", line 274, in _run_raw_task
    TaskInstance._execute_task_with_callbacks(
  File "/home/airflow/.local/lib/python3.8/site-packages/airflow/models/taskinstance.py", line 3161, in _execute_task_with_callbacks
    result = self._execute_task(context, task_orig)
  File "/home/airflow/.local/lib/python3.8/site-packages/airflow/models/taskinstance.py", line 3185, in _execute_task
    return _execute_task(self, context, task_orig)
  File "/home/airflow/.local/lib/python3.8/site-packages/airflow/models/taskinstance.py", line 768, in _execute_task
    result = _execute_callable(context=context, **execute_callable_kwargs)
  File "/home/airflow/.local/lib/python3.8/site-packages/airflow/models/taskinstance.py", line 734, in _execute_callable
    return ExecutionCallableRunner(
  File "/home/airflow/.local/lib/python3.8/site-packages/airflow/utils/operator_helpers.py", line 252, in run
    return self.func(*args, **kwargs)
  File "/home/airflow/.local/lib/python3.8/site-packages/airflow/models/baseoperator.py", line 424, in wrapper
    return func(self, *args, **kwargs)
  File "/home/airflow/.local/lib/python3.8/site-packages/airflow/operators/bash.py", line 276, in execute
    raise AirflowException(
airflow.exceptions.AirflowException: Bash command failed. The command returned a non-zero exit code 2.

During handling of the above exception, another exception occurred:

Traceback (most recent call last):
  File "/home/airflow/.local/lib/python3.8/site-packages/airflow/models/taskinstance.py", line 1443, in _email_alert
    send_email(task.email, subject, html_content)
  File "/home/airflow/.local/lib/python3.8/site-packages/airflow/utils/email.py", line 80, in send_email
    return backend(
  File "/home/airflow/.local/lib/python3.8/site-packages/airflow/utils/email.py", line 155, in send_email_smtp
    send_mime_email(e_from=mail_from, e_to=recipients, mime_msg=msg, conn_id=conn_id, dryrun=dryrun)
  File "/home/airflow/.local/lib/python3.8/site-packages/airflow/utils/email.py", line 274, in send_mime_email
    smtp_conn = _get_smtp_connection(smtp_host, smtp_port, smtp_timeout, smtp_ssl)
  File "/home/airflow/.local/lib/python3.8/site-packages/airflow/utils/email.py", line 318, in _get_smtp_connection
    return smtplib.SMTP(host=host, port=port, timeout=timeout)
  File "/usr/local/lib/python3.8/smtplib.py", line 255, in __init__
    (code, msg) = self.connect(host, port)
  File "/usr/local/lib/python3.8/smtplib.py", line 339, in connect
    self.sock = self._get_socket(host, port, self.timeout)
  File "/usr/local/lib/python3.8/smtplib.py", line 310, in _get_socket
    return socket.create_connection((host, port), timeout,
  File "/usr/local/lib/python3.8/socket.py", line 808, in create_connection
    raise err
  File "/usr/local/lib/python3.8/socket.py", line 796, in create_connection
    sock.connect(sa)
ConnectionRefusedError: [Errno 111] Connection refused

During handling of the above exception, another exception occurred:

Traceback (most recent call last):
  File "/home/airflow/.local/lib/python3.8/site-packages/airflow/models/taskinstance.py", line 1233, in _handle_failure
    task_instance.email_alert(error, failure_context["task"])
  File "/home/airflow/.local/lib/python3.8/site-packages/airflow/models/taskinstance.py", line 3611, in email_alert
    _email_alert(task_instance=self, exception=exception, task=task)
  File "/home/airflow/.local/lib/python3.8/site-packages/airflow/models/taskinstance.py", line 1445, in _email_alert
    send_email(task.email, subject, html_content_err)
  File "/home/airflow/.local/lib/python3.8/site-packages/airflow/utils/email.py", line 80, in send_email
    return backend(
  File "/home/airflow/.local/lib/python3.8/site-packages/airflow/utils/email.py", line 155, in send_email_smtp
    send_mime_email(e_from=mail_from, e_to=recipients, mime_msg=msg, conn_id=conn_id, dryrun=dryrun)
  File "/home/airflow/.local/lib/python3.8/site-packages/airflow/utils/email.py", line 274, in send_mime_email
    smtp_conn = _get_smtp_connection(smtp_host, smtp_port, smtp_timeout, smtp_ssl)
  File "/home/airflow/.local/lib/python3.8/site-packages/airflow/utils/email.py", line 318, in _get_smtp_connection
    return smtplib.SMTP(host=host, port=port, timeout=timeout)
  File "/usr/local/lib/python3.8/smtplib.py", line 255, in __init__
    (code, msg) = self.connect(host, port)
  File "/usr/local/lib/python3.8/smtplib.py", line 339, in connect
    self.sock = self._get_socket(host, port, self.timeout)
  File "/usr/local/lib/python3.8/smtplib.py", line 310, in _get_socket
    return socket.create_connection((host, port), timeout,
  File "/usr/local/lib/python3.8/socket.py", line 808, in create_connection
    raise err
  File "/usr/local/lib/python3.8/socket.py", line 796, in create_connection
    sock.connect(sa)
ConnectionRefusedError: [Errno 111] Connection refused
[2025-10-17T14:10:52.303+0000] {taskinstance.py:341} INFO - ::group::Post task execution logs
[2025-10-17T14:10:52.304+0000] {standard_task_runner.py:124} ERROR - Failed to execute job 28 for task load_bronze (Bash command failed. The command returned a non-zero exit code 2.; 59)
Traceback (most recent call last):
  File "/home/airflow/.local/lib/python3.8/site-packages/airflow/task/task_runner/standard_task_runner.py", line 117, in _start_by_fork
    ret = args.func(args, dag=self.dag)
  File "/home/airflow/.local/lib/python3.8/site-packages/airflow/cli/cli_config.py", line 49, in command
    return func(*args, **kwargs)
  File "/home/airflow/.local/lib/python3.8/site-packages/airflow/utils/cli.py", line 116, in wrapper
    return f(*args, **kwargs)
  File "/home/airflow/.local/lib/python3.8/site-packages/airflow/cli/commands/task_command.py", line 483, in task_run
    task_return_code = _run_task_by_selected_method(args, _dag, ti)
  File "/home/airflow/.local/lib/python3.8/site-packages/airflow/cli/commands/task_command.py", line 256, in _run_task_by_selected_method
    return _run_raw_task(args, ti)
  File "/home/airflow/.local/lib/python3.8/site-packages/airflow/cli/commands/task_command.py", line 341, in _run_raw_task
    return ti._run_raw_task(
  File "/home/airflow/.local/lib/python3.8/site-packages/airflow/utils/session.py", line 97, in wrapper
    return func(*args, session=session, **kwargs)
  File "/home/airflow/.local/lib/python3.8/site-packages/airflow/models/taskinstance.py", line 3006, in _run_raw_task
    return _run_raw_task(
  File "/home/airflow/.local/lib/python3.8/site-packages/airflow/models/taskinstance.py", line 274, in _run_raw_task
    TaskInstance._execute_task_with_callbacks(
  File "/home/airflow/.local/lib/python3.8/site-packages/airflow/models/taskinstance.py", line 3161, in _execute_task_with_callbacks
    result = self._execute_task(context, task_orig)
  File "/home/airflow/.local/lib/python3.8/site-packages/airflow/models/taskinstance.py", line 3185, in _execute_task
    return _execute_task(self, context, task_orig)
  File "/home/airflow/.local/lib/python3.8/site-packages/airflow/models/taskinstance.py", line 768, in _execute_task
    result = _execute_callable(context=context, **execute_callable_kwargs)
  File "/home/airflow/.local/lib/python3.8/site-packages/airflow/models/taskinstance.py", line 734, in _execute_callable
    return ExecutionCallableRunner(
  File "/home/airflow/.local/lib/python3.8/site-packages/airflow/utils/operator_helpers.py", line 252, in run
    return self.func(*args, **kwargs)
  File "/home/airflow/.local/lib/python3.8/site-packages/airflow/models/baseoperator.py", line 424, in wrapper
    return func(self, *args, **kwargs)
  File "/home/airflow/.local/lib/python3.8/site-packages/airflow/operators/bash.py", line 276, in execute
    raise AirflowException(
airflow.exceptions.AirflowException: Bash command failed. The command returned a non-zero exit code 2.
[2025-10-17T14:10:52.354+0000] {local_task_job_runner.py:266} INFO - Task exited with return code 1
[2025-10-17T14:10:52.378+0000] {local_task_job_runner.py:245} INFO - ::endgroup::
